2022-01-17 14:26:13,153 DEBUG    server.py   Инициализация парсера аргументов коммандной строки: ['C:/Users/PanovaM/Desktop/Geekbrains/PyQT/Lesson5/server.py']
2022-01-17 14:26:13,156 DEBUG    server.py   Аргументы успешно загружены.
2022-01-17 14:26:13,156 DEBUG    decos.py    Была вызвана функция arg_parser с параметрами ('7777', ''), {}.Вызов из модуля __main__.Вызов из функции main() компонента server.py
2022-01-17 14:26:13,219 INFO     core.py     Запущен сервер, порт для подключений: 7777, адрес с которого принимаются подключения: . Если адрес не указан, принимаются соединения с любых адресов.
2022-01-17 14:26:23,097 DEBUG    decos.py    Была вызвана функция main с параметрами (), {}.Вызов из модуля __main__.Вызов из функции main() компонента server.py
2022-01-17 15:05:50,269 DEBUG    server.py   Инициализация парсера аргументов коммандной строки: ['C:/Users/PanovaM/Desktop/Geekbrains/PyQT/Lesson5/server.py']
2022-01-17 15:05:50,269 DEBUG    server.py   Аргументы успешно загружены.
2022-01-17 15:05:50,269 DEBUG    decos.py    Была вызвана функция arg_parser с параметрами ('7777', ''), {}.Вызов из модуля __main__.Вызов из функции main() компонента server.py
2022-01-17 15:05:50,281 INFO     core.py     Запущен сервер, порт для подключений: 7777, адрес с которого принимаются подключения: . Если адрес не указан, принимаются соединения с любых адресов.
2022-01-17 15:05:56,285 DEBUG    decos.py    Была вызвана функция arg_parser с параметрами (), {}.Вызов из модуля __main__.Вызов из функции arg_parser() компонента client.py
2022-01-17 15:06:39,310 DEBUG    decos.py    Была вызвана функция arg_parser с параметрами (), {}.Вызов из модуля __main__.Вызов из функции arg_parser() компонента client.py
2022-01-17 15:23:34,560 DEBUG    decos.py    Была вызвана функция arg_parser с параметрами (), {}.Вызов из модуля __main__.Вызов из функции arg_parser() компонента client.py
2022-01-17 15:23:46,610 INFO     core.py     Установлено соедение с ПК ('127.0.0.1', 50603)
2022-01-17 16:36:05,800 DEBUG    decos.py    Была вызвана функция arg_parser с параметрами (), {}.Вызов из модуля __main__.Вызов из функции arg_parser() компонента client.py
2022-01-17 16:38:40,688 DEBUG    decos.py    Была вызвана функция main с параметрами (), {}.Вызов из модуля __main__.Вызов из функции main() компонента server.py
2022-01-17 16:38:49,269 DEBUG    server.py   Инициализация парсера аргументов коммандной строки: ['C:/Users/PanovaM/Desktop/Geekbrains/PyQT/Lesson5/server.py']
2022-01-17 16:38:49,269 DEBUG    server.py   Аргументы успешно загружены.
2022-01-17 16:38:49,269 DEBUG    decos.py    Была вызвана функция arg_parser с параметрами ('7777', ''), {}.Вызов из модуля __main__.Вызов из функции main() компонента server.py
2022-01-17 16:38:49,285 INFO     core.py     Запущен сервер, порт для подключений: 7777, адрес с которого принимаются подключения: . Если адрес не указан, принимаются соединения с любых адресов.
2022-01-17 16:47:44,774 DEBUG    server.py   Инициализация парсера аргументов коммандной строки: ['C:/Users/PanovaM/Desktop/Geekbrains/PyQT/Lesson5/server.py']
2022-01-17 16:47:44,774 DEBUG    server.py   Аргументы успешно загружены.
2022-01-17 16:47:44,774 DEBUG    decos.py    Была вызвана функция arg_parser с параметрами ('7777', ''), {}.Вызов из модуля __main__.Вызов из функции main() компонента server.py
2022-01-17 16:47:44,841 INFO     core.py     Запущен сервер, порт для подключений: 7777, адрес с которого принимаются подключения: . Если адрес не указан, принимаются соединения с любых адресов.
2022-01-17 16:51:59,585 DEBUG    server.py   Инициализация парсера аргументов коммандной строки: ['C:/Users/PanovaM/Desktop/Geekbrains/PyQT/Lesson5/server.py']
2022-01-17 16:51:59,585 DEBUG    server.py   Аргументы успешно загружены.
2022-01-17 16:51:59,585 DEBUG    decos.py    Была вызвана функция arg_parser с параметрами ('7777', ''), {}.Вызов из модуля __main__.Вызов из функции main() компонента server.py
2022-01-17 16:51:59,618 INFO     core.py     Запущен сервер, порт для подключений: 7777, адрес с которого принимаются подключения: . Если адрес не указан, принимаются соединения с любых адресов.
2022-01-17 16:53:24,481 DEBUG    server.py   Инициализация парсера аргументов коммандной строки: ['C:/Users/PanovaM/Desktop/Geekbrains/PyQT/Lesson5/server.py']
2022-01-17 16:53:24,481 DEBUG    server.py   Аргументы успешно загружены.
2022-01-17 16:53:24,481 DEBUG    decos.py    Была вызвана функция arg_parser с параметрами ('7777', ''), {}.Вызов из модуля __main__.Вызов из функции main() компонента server.py
2022-01-17 16:53:24,512 INFO     core.py     Запущен сервер, порт для подключений: 7777, адрес с которого принимаются подключения: . Если адрес не указан, принимаются соединения с любых адресов.
2022-01-17 16:54:39,896 DEBUG    server.py   Инициализация парсера аргументов коммандной строки: ['C:/Users/PanovaM/Desktop/Geekbrains/PyQT/Lesson5/server.py']
2022-01-17 16:54:39,912 DEBUG    server.py   Аргументы успешно загружены.
2022-01-17 16:54:39,912 DEBUG    decos.py    Была вызвана функция arg_parser с параметрами ('7777', ''), {}.Вызов из модуля __main__.Вызов из функции main() компонента server.py
2022-01-17 16:54:39,928 INFO     core.py     Запущен сервер, порт для подключений: 7777, адрес с которого принимаются подключения: . Если адрес не указан, принимаются соединения с любых адресов.
2022-01-17 17:00:37,679 DEBUG    server.py   Инициализация парсера аргументов коммандной строки: ['C:/Users/PanovaM/Desktop/Geekbrains/PyQT/Lesson5/server.py']
2022-01-17 17:00:37,679 DEBUG    server.py   Аргументы успешно загружены.
2022-01-17 17:00:37,679 DEBUG    decos.py    Была вызвана функция arg_parser с параметрами ('7777', ''), {}.Вызов из модуля __main__.Вызов из функции main() компонента server.py
2022-01-17 17:00:37,695 INFO     core.py     Запущен сервер, порт для подключений: 7777, адрес с которого принимаются подключения: . Если адрес не указан, принимаются соединения с любых адресов.
2022-01-17 17:01:28,310 DEBUG    server.py   Инициализация парсера аргументов коммандной строки: ['C:/Users/PanovaM/Desktop/Geekbrains/PyQT/Lesson5/server.py']
2022-01-17 17:01:28,312 DEBUG    server.py   Аргументы успешно загружены.
2022-01-17 17:01:28,313 DEBUG    decos.py    Была вызвана функция arg_parser с параметрами ('7777', ''), {}.Вызов из модуля __main__.Вызов из функции main() компонента server.py
2022-01-17 17:01:28,334 INFO     core.py     Запущен сервер, порт для подключений: 7777, адрес с которого принимаются подключения: . Если адрес не указан, принимаются соединения с любых адресов.
2022-01-17 17:01:46,337 DEBUG    decos.py    Была вызвана функция main с параметрами (), {}.Вызов из модуля __main__.Вызов из функции main() компонента server.py
2022-01-17 17:02:53,211 DEBUG    server.py   Инициализация парсера аргументов коммандной строки: ['C:/Users/PanovaM/Desktop/Geekbrains/PyQT/Lesson5/server.py']
2022-01-17 17:02:53,227 DEBUG    server.py   Аргументы успешно загружены.
2022-01-17 17:02:53,227 DEBUG    decos.py    Была вызвана функция arg_parser с параметрами ('7777', ''), {}.Вызов из модуля __main__.Вызов из функции main() компонента server.py
2022-01-17 17:02:53,242 INFO     core.py     Запущен сервер, порт для подключений: 7777, адрес с которого принимаются подключения: . Если адрес не указан, принимаются соединения с любых адресов.
2022-01-17 17:05:55,323 DEBUG    server.py   Инициализация парсера аргументов коммандной строки: ['C:/Users/PanovaM/Desktop/Geekbrains/PyQT/Lesson5/server.py']
2022-01-17 17:05:55,323 DEBUG    server.py   Аргументы успешно загружены.
2022-01-17 17:05:55,323 DEBUG    decos.py    Была вызвана функция arg_parser с параметрами ('7777', ''), {}.Вызов из модуля __main__.Вызов из функции main() компонента server.py
2022-01-17 17:05:55,338 INFO     core.py     Запущен сервер, порт для подключений: 7777, адрес с которого принимаются подключения: . Если адрес не указан, принимаются соединения с любых адресов.
2022-01-17 17:07:36,592 DEBUG    server.py   Инициализация парсера аргументов коммандной строки: ['server.py']
2022-01-17 17:07:36,592 DEBUG    server.py   Аргументы успешно загружены.
2022-01-17 17:07:36,592 DEBUG    decos.py    Была вызвана функция arg_parser с параметрами ('7777', ''), {}.Вызов из модуля __main__.Вызов из функции main() компонента server.py
2022-01-17 17:07:36,623 INFO     core.py     Запущен сервер, порт для подключений: 7777, адрес с которого принимаются подключения: . Если адрес не указан, принимаются соединения с любых адресов.
2022-01-17 17:08:02,471 DEBUG    server.py   Инициализация парсера аргументов коммандной строки: ['server.py']
2022-01-17 17:08:02,471 DEBUG    server.py   Аргументы успешно загружены.
2022-01-17 17:08:02,471 DEBUG    decos.py    Была вызвана функция arg_parser с параметрами ('7777', ''), {}.Вызов из модуля __main__.Вызов из функции main() компонента server.py
2022-01-17 17:08:02,488 INFO     core.py     Запущен сервер, порт для подключений: 7777, адрес с которого принимаются подключения: . Если адрес не указан, принимаются соединения с любых адресов.
2022-01-17 17:08:09,166 DEBUG    decos.py    Была вызвана функция arg_parser с параметрами (), {}.Вызов из модуля __main__.Вызов из функции arg_parser() компонента client.py
2022-01-17 17:08:09,166 DEBUG    decos.py    Была вызвана функция arg_parser с параметрами (), {}.Вызов из модуля __main__.Вызов из функции arg_parser() компонента client.py
2022-01-17 17:08:09,648 INFO     core.py     Установлено соедение с ПК ('127.0.0.1', 62104)
2022-01-17 17:08:10,150 DEBUG    core.py     Start auth process for {'account_name': 'test1', 'pubkey': '-----BEGIN PUBLIC KEY-----\nMIIBIjANBgkqhkiG9w0BAQEFAAOCAQ8AMIIBCgKCAQEAiIvkZ/4aFCOitj4mqHCU\nb0Vw3v+HLBHFFx3dNAsGh49AbIBkt7DqCEIPtOFLbJrLuyrN/zYfp2KJW0B0dmJ8\nViJ3y1LI0u+ZuVJL+GSLtMzO5v1M9h+D2tetKU20wuh/xqqcsGq5kaJ+tTDQ1Xsi\ngP1aj+gqhSu4/rG72PEmosvTp/AX35i/E1WufsUi/MI2xJ4lwVEyVWaTSUo9GClJ\nQl38CkAJubuyRxVNvcLYm1ZfWuTs4ZFMVOcyhqDk3LQrnAl/RT5MNKhvmOXbJeWx\npTF6x36RMm8X5T+/50c2gGpske0wl3v2732mbHmbVWdsurwosLU4XXx0RA6LiRs8\ncwIDAQAB\n-----END PUBLIC KEY-----'}
2022-01-17 17:08:10,150 DEBUG    core.py     Correct username, starting passwd check.
2022-01-17 17:08:10,150 DEBUG    core.py     Auth message = {'response': 511, 'bin': '63816b854902cc0a93f256f24ea2a425a5f6115a6e9279c570895c0694f68a5a7522d816f78d45af9da1d6340b08bc2f0931e9390a0eb02df13584a8a12847ea'}
2022-01-17 17:08:10,150 DEBUG    core.py     Getting data from client exception.
Traceback (most recent call last):
  File "C:\Users\PanovaM\Desktop\Geekbrains\PyQT\Lesson5\server_file\core.py", line 75, in run
    self.process_client_massage(
  File "C:\Users\PanovaM\Desktop\Geekbrains\PyQT\Lesson5\server_file\core.py", line 115, in process_client_massage
    self.autorize_user(message, client)
  File "C:\Users\PanovaM\Desktop\Geekbrains\PyQT\Lesson5\server_file\core.py", line 265, in autorize_user
    self.database.user_login(
TypeError: user_login() takes 4 positional arguments but 5 were given
2022-01-17 17:08:10,150 INFO     core.py     Клиент ('127.0.0.1', 62104) отключился от сервера.
2022-01-17 17:08:11,501 INFO     core.py     Установлено соедение с ПК ('127.0.0.1', 62106)
2022-01-17 17:08:12,004 DEBUG    core.py     Start auth process for {'account_name': 'test2', 'pubkey': '-----BEGIN PUBLIC KEY-----\nMIIBIjANBgkqhkiG9w0BAQEFAAOCAQ8AMIIBCgKCAQEAsyD82XiFWNTzk+5xwsfE\n8YiiWULjCjErkmqWNlVxeL40oqdHiG8TLbV/hLa9qbu4+52ntx/ev9fRc+ixvrr6\niq+y+eieI9yitBVTfLiFFMQtGi0DjYVVdGjplvtljCQxchC3rmF9yu44r14jPP5W\nCsn7DoYoSOmQtKt3a0YzpsNFa4d6wXhVIvmuAhsuPNi6rfnLNCL49XyzWtoCHEVN\nOVsJpO6Zmsyc/Q5irHfjZ5krJEV9dxPAaQkzdTXmCRh3OEL0OZ9zJpVPbV/bGtuc\nIbNZwSh2C+aPL+65ux2v0pXEyBSnjDLq9UiRnJ/mVl+VYbI/1KhKxRZnruE8Dbvw\nzwIDAQAB\n-----END PUBLIC KEY-----'}
2022-01-17 17:08:12,004 DEBUG    core.py     Correct username, starting passwd check.
2022-01-17 17:08:12,004 DEBUG    core.py     Auth message = {'response': 511, 'bin': '6c3f6e3ddcb051136e14e5c1c097c3aa277563cd5e85888b06856c57552f1ee467b60d11e4f6a76794023532a0524be6cca105100b682690b9712db197dd1c3b'}
2022-01-17 17:08:12,004 DEBUG    core.py     Getting data from client exception.
Traceback (most recent call last):
  File "C:\Users\PanovaM\Desktop\Geekbrains\PyQT\Lesson5\server_file\core.py", line 75, in run
    self.process_client_massage(
  File "C:\Users\PanovaM\Desktop\Geekbrains\PyQT\Lesson5\server_file\core.py", line 115, in process_client_massage
    self.autorize_user(message, client)
  File "C:\Users\PanovaM\Desktop\Geekbrains\PyQT\Lesson5\server_file\core.py", line 265, in autorize_user
    self.database.user_login(
TypeError: user_login() takes 4 positional arguments but 5 were given
2022-01-17 17:08:12,004 INFO     core.py     Клиент ('127.0.0.1', 62106) отключился от сервера.
2022-01-17 17:08:33,090 DEBUG    decos.py    Была вызвана функция arg_parser с параметрами (), {}.Вызов из модуля __main__.Вызов из функции arg_parser() компонента client.py
2022-01-17 17:08:44,301 INFO     core.py     Установлено соедение с ПК ('127.0.0.1', 62229)
2022-01-17 17:08:44,810 DEBUG    core.py     Start auth process for {'account_name': 'test1', 'pubkey': '-----BEGIN PUBLIC KEY-----\nMIIBIjANBgkqhkiG9w0BAQEFAAOCAQ8AMIIBCgKCAQEAiIvkZ/4aFCOitj4mqHCU\nb0Vw3v+HLBHFFx3dNAsGh49AbIBkt7DqCEIPtOFLbJrLuyrN/zYfp2KJW0B0dmJ8\nViJ3y1LI0u+ZuVJL+GSLtMzO5v1M9h+D2tetKU20wuh/xqqcsGq5kaJ+tTDQ1Xsi\ngP1aj+gqhSu4/rG72PEmosvTp/AX35i/E1WufsUi/MI2xJ4lwVEyVWaTSUo9GClJ\nQl38CkAJubuyRxVNvcLYm1ZfWuTs4ZFMVOcyhqDk3LQrnAl/RT5MNKhvmOXbJeWx\npTF6x36RMm8X5T+/50c2gGpske0wl3v2732mbHmbVWdsurwosLU4XXx0RA6LiRs8\ncwIDAQAB\n-----END PUBLIC KEY-----'}
2022-01-17 17:08:44,812 DEBUG    core.py     Correct username, starting passwd check.
2022-01-17 17:08:44,814 DEBUG    core.py     Auth message = {'response': 511, 'bin': '06434cef82a3741e16203047e334acc68c088675da1f105a9f30ae681c1224e2e8da57f61c5c39a3c7aeb2ad51f09a6197e86ca384c32303a55cc95c54dcaa9e'}
2022-01-17 17:08:44,816 DEBUG    core.py     Getting data from client exception.
Traceback (most recent call last):
  File "C:\Users\PanovaM\Desktop\Geekbrains\PyQT\Lesson5\server_file\core.py", line 75, in run
    self.process_client_massage(
  File "C:\Users\PanovaM\Desktop\Geekbrains\PyQT\Lesson5\server_file\core.py", line 115, in process_client_massage
    self.autorize_user(message, client)
  File "C:\Users\PanovaM\Desktop\Geekbrains\PyQT\Lesson5\server_file\core.py", line 265, in autorize_user
    self.database.user_login(
TypeError: user_login() takes 4 positional arguments but 5 were given
2022-01-17 17:08:44,817 INFO     core.py     Клиент ('127.0.0.1', 62229) отключился от сервера.
2022-01-17 17:14:53,758 DEBUG    server.py   Инициализация парсера аргументов коммандной строки: ['C:/Users/PanovaM/Desktop/Geekbrains/PyQT/Lesson5/server.py']
2022-01-17 17:14:53,758 DEBUG    server.py   Аргументы успешно загружены.
2022-01-17 17:14:53,758 DEBUG    decos.py    Была вызвана функция arg_parser с параметрами ('7777', ''), {}.Вызов из модуля __main__.Вызов из функции main() компонента server.py
2022-01-17 17:14:53,773 INFO     core.py     Запущен сервер, порт для подключений: 7777, адрес с которого принимаются подключения: . Если адрес не указан, принимаются соединения с любых адресов.
2022-01-17 17:15:05,121 DEBUG    decos.py    Была вызвана функция main с параметрами (), {}.Вызов из модуля __main__.Вызов из функции main() компонента server.py
2022-01-17 17:15:11,687 DEBUG    decos.py    Была вызвана функция main с параметрами (), {}.Вызов из модуля __main__.Вызов из функции main() компонента server.py
2022-01-17 17:15:14,580 DEBUG    server.py   Инициализация парсера аргументов коммандной строки: ['C:/Users/PanovaM/Desktop/Geekbrains/PyQT/Lesson5/server.py']
2022-01-17 17:15:14,580 DEBUG    server.py   Аргументы успешно загружены.
2022-01-17 17:15:14,596 DEBUG    decos.py    Была вызвана функция arg_parser с параметрами ('7777', ''), {}.Вызов из модуля __main__.Вызов из функции main() компонента server.py
2022-01-17 17:15:14,612 INFO     core.py     Запущен сервер, порт для подключений: 7777, адрес с которого принимаются подключения: . Если адрес не указан, принимаются соединения с любых адресов.
2022-01-17 17:15:25,905 DEBUG    decos.py    Была вызвана функция arg_parser с параметрами (), {}.Вызов из модуля __main__.Вызов из функции arg_parser() компонента client.py
2022-01-17 17:15:33,898 INFO     core.py     Установлено соедение с ПК ('127.0.0.1', 63563)
2022-01-17 17:15:34,413 DEBUG    core.py     Start auth process for {'account_name': 'test1', 'pubkey': '-----BEGIN PUBLIC KEY-----\nMIIBIjANBgkqhkiG9w0BAQEFAAOCAQ8AMIIBCgKCAQEAiIvkZ/4aFCOitj4mqHCU\nb0Vw3v+HLBHFFx3dNAsGh49AbIBkt7DqCEIPtOFLbJrLuyrN/zYfp2KJW0B0dmJ8\nViJ3y1LI0u+ZuVJL+GSLtMzO5v1M9h+D2tetKU20wuh/xqqcsGq5kaJ+tTDQ1Xsi\ngP1aj+gqhSu4/rG72PEmosvTp/AX35i/E1WufsUi/MI2xJ4lwVEyVWaTSUo9GClJ\nQl38CkAJubuyRxVNvcLYm1ZfWuTs4ZFMVOcyhqDk3LQrnAl/RT5MNKhvmOXbJeWx\npTF6x36RMm8X5T+/50c2gGpske0wl3v2732mbHmbVWdsurwosLU4XXx0RA6LiRs8\ncwIDAQAB\n-----END PUBLIC KEY-----'}
2022-01-17 17:15:34,419 DEBUG    core.py     Correct username, starting passwd check.
2022-01-17 17:15:34,420 DEBUG    core.py     Auth message = {'response': 511, 'bin': 'e6ce1c9bef55d29a69264c4a8f191a0c8da8f6ea24acc92e425981a8c5398b7f79ec15c10eb0b7978b3cd734d18c89ba89e0902cd5386e428829af5826018e83'}
2022-01-17 17:15:34,422 DEBUG    core.py     Getting data from client exception.
Traceback (most recent call last):
  File "C:\Users\PanovaM\Desktop\Geekbrains\PyQT\Lesson5\server_file\core.py", line 75, in run
    self.process_client_massage(
  File "C:\Users\PanovaM\Desktop\Geekbrains\PyQT\Lesson5\server_file\core.py", line 115, in process_client_massage
    self.autorize_user(message, client)
  File "C:\Users\PanovaM\Desktop\Geekbrains\PyQT\Lesson5\server_file\core.py", line 265, in autorize_user
    self.database.user_login(
TypeError: user_login() takes 4 positional arguments but 5 were given
2022-01-17 17:15:34,423 INFO     core.py     Клиент ('127.0.0.1', 63563) отключился от сервера.
2022-01-17 17:21:48,017 DEBUG    server.py   Инициализация парсера аргументов коммандной строки: ['C:/Users/PanovaM/Desktop/Geekbrains/PyQT/Lesson5/server.py']
2022-01-17 17:21:48,017 DEBUG    server.py   Аргументы успешно загружены.
2022-01-17 17:21:48,017 DEBUG    decos.py    Была вызвана функция arg_parser с параметрами ('7777', ''), {}.Вызов из модуля __main__.Вызов из функции main() компонента server.py
2022-01-17 17:21:48,067 INFO     core.py     Запущен сервер, порт для подключений: 7777, адрес с которого принимаются подключения: . Если адрес не указан, принимаются соединения с любых адресов.
2022-01-17 17:22:05,706 DEBUG    decos.py    Была вызвана функция arg_parser с параметрами (), {}.Вызов из модуля __main__.Вызов из функции arg_parser() компонента client.py
2022-01-17 17:22:13,869 INFO     core.py     Установлено соедение с ПК ('127.0.0.1', 64414)
2022-01-17 17:22:14,377 DEBUG    core.py     Start auth process for {'account_name': 'test1', 'pubkey': '-----BEGIN PUBLIC KEY-----\nMIIBIjANBgkqhkiG9w0BAQEFAAOCAQ8AMIIBCgKCAQEAiIvkZ/4aFCOitj4mqHCU\nb0Vw3v+HLBHFFx3dNAsGh49AbIBkt7DqCEIPtOFLbJrLuyrN/zYfp2KJW0B0dmJ8\nViJ3y1LI0u+ZuVJL+GSLtMzO5v1M9h+D2tetKU20wuh/xqqcsGq5kaJ+tTDQ1Xsi\ngP1aj+gqhSu4/rG72PEmosvTp/AX35i/E1WufsUi/MI2xJ4lwVEyVWaTSUo9GClJ\nQl38CkAJubuyRxVNvcLYm1ZfWuTs4ZFMVOcyhqDk3LQrnAl/RT5MNKhvmOXbJeWx\npTF6x36RMm8X5T+/50c2gGpske0wl3v2732mbHmbVWdsurwosLU4XXx0RA6LiRs8\ncwIDAQAB\n-----END PUBLIC KEY-----'}
2022-01-17 17:22:14,378 DEBUG    core.py     Correct username, starting passwd check.
2022-01-17 17:22:14,382 DEBUG    core.py     Auth message = {'response': 511, 'bin': 'f02fd33a95a9fbcdfe91a9ca360101e5f74603940eb4cf3e97f5279963c33fc528b3047d20d32bc6ac32852af01cd2fbee4d49b0a1d75c05a1b934366d87b5c8'}
2022-01-17 17:22:15,406 DEBUG    core.py     Getting data from client exception.
Traceback (most recent call last):
  File "C:\Users\PanovaM\Desktop\Geekbrains\PyQT\Lesson5\server_file\core.py", line 76, in run
    get_message(client_with_message), client_with_message)
  File "C:\Users\PanovaM\Desktop\Geekbrains\PyQT\Lesson5\common\utils.py", line 19, in get_message
    response = json.loads(json_response)
  File "C:\Users\PanovaM\AppData\Local\Programs\Python\Python39\lib\json\__init__.py", line 346, in loads
    return _default_decoder.decode(s)
  File "C:\Users\PanovaM\AppData\Local\Programs\Python\Python39\lib\json\decoder.py", line 337, in decode
    obj, end = self.raw_decode(s, idx=_w(s, 0).end())
  File "C:\Users\PanovaM\AppData\Local\Programs\Python\Python39\lib\json\decoder.py", line 355, in raw_decode
    raise JSONDecodeError("Expecting value", s, err.value) from None
json.decoder.JSONDecodeError: Expecting value: line 1 column 1 (char 0)
2022-01-17 17:22:15,433 INFO     core.py     Клиент ('127.0.0.1', 64414) отключился от сервера.
2022-01-17 17:24:13,385 DEBUG    server.py   Инициализация парсера аргументов коммандной строки: ['C:/Users/PanovaM/Desktop/Geekbrains/PyQT/Lesson5/server.py']
2022-01-17 17:24:13,385 DEBUG    server.py   Аргументы успешно загружены.
2022-01-17 17:24:13,385 DEBUG    decos.py    Была вызвана функция arg_parser с параметрами ('7777', ''), {}.Вызов из модуля __main__.Вызов из функции main() компонента server.py
2022-01-17 17:24:13,438 INFO     core.py     Запущен сервер, порт для подключений: 7777, адрес с которого принимаются подключения: . Если адрес не указан, принимаются соединения с любых адресов.
2022-01-17 17:26:01,775 DEBUG    decos.py    Была вызвана функция arg_parser с параметрами (), {}.Вызов из модуля __main__.Вызов из функции arg_parser() компонента client.py
2022-01-17 17:26:17,996 INFO     core.py     Установлено соедение с ПК ('127.0.0.1', 64603)
2022-01-17 17:26:18,508 DEBUG    core.py     Start auth process for {'account_name': 'test1', 'pubkey': '-----BEGIN PUBLIC KEY-----\nMIIBIjANBgkqhkiG9w0BAQEFAAOCAQ8AMIIBCgKCAQEAiIvkZ/4aFCOitj4mqHCU\nb0Vw3v+HLBHFFx3dNAsGh49AbIBkt7DqCEIPtOFLbJrLuyrN/zYfp2KJW0B0dmJ8\nViJ3y1LI0u+ZuVJL+GSLtMzO5v1M9h+D2tetKU20wuh/xqqcsGq5kaJ+tTDQ1Xsi\ngP1aj+gqhSu4/rG72PEmosvTp/AX35i/E1WufsUi/MI2xJ4lwVEyVWaTSUo9GClJ\nQl38CkAJubuyRxVNvcLYm1ZfWuTs4ZFMVOcyhqDk3LQrnAl/RT5MNKhvmOXbJeWx\npTF6x36RMm8X5T+/50c2gGpske0wl3v2732mbHmbVWdsurwosLU4XXx0RA6LiRs8\ncwIDAQAB\n-----END PUBLIC KEY-----'}
2022-01-17 17:26:18,511 DEBUG    core.py     Correct username, starting passwd check.
2022-01-17 17:26:18,513 DEBUG    core.py     Auth message = {'response': 511, 'bin': '54e000f406e00f19d4bd97e4bec7b925d355dfd6900d5f91bc8c88f0c53126420482e1ea2ce978bb24bc0088e9e16b90d90c82878c968e6c481042dfd2202fb0'}
2022-01-17 17:26:20,076 DEBUG    core.py     Getting data from client exception.
Traceback (most recent call last):
  File "C:\Users\PanovaM\Desktop\Geekbrains\PyQT\Lesson5\server_file\core.py", line 76, in run
    get_message(client_with_message), client_with_message)
  File "C:\Users\PanovaM\Desktop\Geekbrains\PyQT\Lesson5\common\utils.py", line 16, in get_message
    encoded_response = client.recv(MAX_PACAGE_LEGTH)
ConnectionResetError: [WinError 10054] Удаленный хост принудительно разорвал существующее подключение
2022-01-17 17:26:20,077 INFO     core.py     Клиент ('127.0.0.1', 64603) отключился от сервера.
2022-01-17 17:30:28,040 DEBUG    server.py   Инициализация парсера аргументов коммандной строки: ['C:/Users/PanovaM/Desktop/Geekbrains/PyQT/Lesson5/server.py']
2022-01-17 17:30:28,040 DEBUG    server.py   Аргументы успешно загружены.
2022-01-17 17:30:28,040 DEBUG    decos.py    Была вызвана функция arg_parser с параметрами ('7777', ''), {}.Вызов из модуля __main__.Вызов из функции main() компонента server.py
2022-01-17 17:30:28,085 INFO     core.py     Запущен сервер, порт для подключений: 7777, адрес с которого принимаются подключения: . Если адрес не указан, принимаются соединения с любых адресов.
2022-01-17 17:30:43,611 DEBUG    decos.py    Была вызвана функция arg_parser с параметрами (), {}.Вызов из модуля __main__.Вызов из функции arg_parser() компонента client.py
2022-01-17 17:30:49,352 INFO     core.py     Установлено соедение с ПК ('127.0.0.1', 64809)
2022-01-17 17:30:49,853 DEBUG    core.py     Start auth process for {'account_name': 'test1', 'pubkey': '-----BEGIN PUBLIC KEY-----\nMIIBIjANBgkqhkiG9w0BAQEFAAOCAQ8AMIIBCgKCAQEAiIvkZ/4aFCOitj4mqHCU\nb0Vw3v+HLBHFFx3dNAsGh49AbIBkt7DqCEIPtOFLbJrLuyrN/zYfp2KJW0B0dmJ8\nViJ3y1LI0u+ZuVJL+GSLtMzO5v1M9h+D2tetKU20wuh/xqqcsGq5kaJ+tTDQ1Xsi\ngP1aj+gqhSu4/rG72PEmosvTp/AX35i/E1WufsUi/MI2xJ4lwVEyVWaTSUo9GClJ\nQl38CkAJubuyRxVNvcLYm1ZfWuTs4ZFMVOcyhqDk3LQrnAl/RT5MNKhvmOXbJeWx\npTF6x36RMm8X5T+/50c2gGpske0wl3v2732mbHmbVWdsurwosLU4XXx0RA6LiRs8\ncwIDAQAB\n-----END PUBLIC KEY-----'}
2022-01-17 17:30:49,855 DEBUG    core.py     Correct username, starting passwd check.
2022-01-17 17:30:49,857 DEBUG    core.py     Auth message = {'response': 511, 'bin': 'f0798ef484b3df8df2cce69c120f7efa9951ed6596d7045fe3da22e900d0bf94365c5a589e0a99d4a6812d2d897a2ee5db47ea4c058557d4b71fa0d00ce157a5'}
2022-01-17 17:30:51,398 DEBUG    core.py     Getting data from client exception.
Traceback (most recent call last):
  File "C:\Users\PanovaM\Desktop\Geekbrains\PyQT\Lesson5\server_file\core.py", line 76, in run
    get_message(client_with_message), client_with_message)
  File "C:\Users\PanovaM\Desktop\Geekbrains\PyQT\Lesson5\common\utils.py", line 16, in get_message
    encoded_response = client.recv(MAX_PACAGE_LEGTH)
ConnectionResetError: [WinError 10054] Удаленный хост принудительно разорвал существующее подключение
2022-01-17 17:30:51,399 INFO     core.py     Клиент ('127.0.0.1', 64809) отключился от сервера.
2022-01-17 17:34:12,031 DEBUG    decos.py    Была вызвана функция arg_parser с параметрами (), {}.Вызов из модуля __main__.Вызов из функции arg_parser() компонента client.py
2022-01-17 17:34:21,402 INFO     core.py     Установлено соедение с ПК ('127.0.0.1', 65472)
2022-01-17 17:34:21,905 DEBUG    core.py     Start auth process for {'account_name': 'test1', 'pubkey': '-----BEGIN PUBLIC KEY-----\nMIIBIjANBgkqhkiG9w0BAQEFAAOCAQ8AMIIBCgKCAQEAiIvkZ/4aFCOitj4mqHCU\nb0Vw3v+HLBHFFx3dNAsGh49AbIBkt7DqCEIPtOFLbJrLuyrN/zYfp2KJW0B0dmJ8\nViJ3y1LI0u+ZuVJL+GSLtMzO5v1M9h+D2tetKU20wuh/xqqcsGq5kaJ+tTDQ1Xsi\ngP1aj+gqhSu4/rG72PEmosvTp/AX35i/E1WufsUi/MI2xJ4lwVEyVWaTSUo9GClJ\nQl38CkAJubuyRxVNvcLYm1ZfWuTs4ZFMVOcyhqDk3LQrnAl/RT5MNKhvmOXbJeWx\npTF6x36RMm8X5T+/50c2gGpske0wl3v2732mbHmbVWdsurwosLU4XXx0RA6LiRs8\ncwIDAQAB\n-----END PUBLIC KEY-----'}
2022-01-17 17:34:21,906 DEBUG    core.py     Correct username, starting passwd check.
2022-01-17 17:34:21,907 DEBUG    core.py     Auth message = {'response': 511, 'bin': 'cef1d72a42948cd651a3942a9880ba76d29e029e0651847ebee373f30ada005e2ad535478bdbabb5e3592a95805b25a4f1a46ad25f4a4fe0d4f03261cc668a94'}
2022-01-17 17:34:23,429 DEBUG    core.py     Getting data from client exception.
Traceback (most recent call last):
  File "C:\Users\PanovaM\Desktop\Geekbrains\PyQT\Lesson5\server_file\core.py", line 76, in run
    get_message(client_with_message), client_with_message)
  File "C:\Users\PanovaM\Desktop\Geekbrains\PyQT\Lesson5\common\utils.py", line 16, in get_message
    encoded_response = client.recv(MAX_PACAGE_LEGTH)
ConnectionResetError: [WinError 10054] Удаленный хост принудительно разорвал существующее подключение
2022-01-17 17:34:23,429 INFO     core.py     Клиент ('127.0.0.1', 65472) отключился от сервера.
2022-01-17 17:36:01,067 DEBUG    decos.py    Была вызвана функция arg_parser с параметрами (), {}.Вызов из модуля __main__.Вызов из функции arg_parser() компонента client.py
2022-01-17 17:36:05,991 INFO     core.py     Установлено соедение с ПК ('127.0.0.1', 49384)
2022-01-17 17:36:06,495 DEBUG    core.py     Start auth process for {'account_name': 'test1', 'pubkey': '-----BEGIN PUBLIC KEY-----\nMIIBIjANBgkqhkiG9w0BAQEFAAOCAQ8AMIIBCgKCAQEAiIvkZ/4aFCOitj4mqHCU\nb0Vw3v+HLBHFFx3dNAsGh49AbIBkt7DqCEIPtOFLbJrLuyrN/zYfp2KJW0B0dmJ8\nViJ3y1LI0u+ZuVJL+GSLtMzO5v1M9h+D2tetKU20wuh/xqqcsGq5kaJ+tTDQ1Xsi\ngP1aj+gqhSu4/rG72PEmosvTp/AX35i/E1WufsUi/MI2xJ4lwVEyVWaTSUo9GClJ\nQl38CkAJubuyRxVNvcLYm1ZfWuTs4ZFMVOcyhqDk3LQrnAl/RT5MNKhvmOXbJeWx\npTF6x36RMm8X5T+/50c2gGpske0wl3v2732mbHmbVWdsurwosLU4XXx0RA6LiRs8\ncwIDAQAB\n-----END PUBLIC KEY-----'}
2022-01-17 17:36:06,497 DEBUG    core.py     Correct username, starting passwd check.
2022-01-17 17:36:06,498 DEBUG    core.py     Auth message = {'response': 511, 'bin': '1a3e60cdbe7f90f6b1aafeab645d70f722cdc0f1a864295afd9a789b9ba524a0dba6be79cabcbfff67d6d880672c4bc01f91d6ef4728b0e39a48a979f15fcf95'}
2022-01-17 17:38:09,223 DEBUG    server.py   Инициализация парсера аргументов коммандной строки: ['server.py']
2022-01-17 17:38:09,223 DEBUG    server.py   Аргументы успешно загружены.
2022-01-17 17:38:09,223 DEBUG    decos.py    Была вызвана функция arg_parser с параметрами ('7777', ''), {}.Вызов из модуля __main__.Вызов из функции main() компонента server.py
2022-01-17 17:38:09,239 INFO     core.py     Запущен сервер, порт для подключений: 7777, адрес с которого принимаются подключения: . Если адрес не указан, принимаются соединения с любых адресов.
2022-01-17 17:38:16,743 DEBUG    decos.py    Была вызвана функция arg_parser с параметрами (), {}.Вызов из модуля __main__.Вызов из функции arg_parser() компонента client.py
2022-01-17 17:38:16,743 DEBUG    decos.py    Была вызвана функция arg_parser с параметрами (), {}.Вызов из модуля __main__.Вызов из функции arg_parser() компонента client.py
2022-01-17 17:38:17,133 INFO     core.py     Установлено соедение с ПК ('127.0.0.1', 50124)
2022-01-17 17:38:17,159 INFO     core.py     Установлено соедение с ПК ('127.0.0.1', 50125)
2022-01-17 17:38:17,159 DEBUG    core.py     Start auth process for {'account_name': 'test1', 'pubkey': '-----BEGIN PUBLIC KEY-----\nMIIBIjANBgkqhkiG9w0BAQEFAAOCAQ8AMIIBCgKCAQEAiIvkZ/4aFCOitj4mqHCU\nb0Vw3v+HLBHFFx3dNAsGh49AbIBkt7DqCEIPtOFLbJrLuyrN/zYfp2KJW0B0dmJ8\nViJ3y1LI0u+ZuVJL+GSLtMzO5v1M9h+D2tetKU20wuh/xqqcsGq5kaJ+tTDQ1Xsi\ngP1aj+gqhSu4/rG72PEmosvTp/AX35i/E1WufsUi/MI2xJ4lwVEyVWaTSUo9GClJ\nQl38CkAJubuyRxVNvcLYm1ZfWuTs4ZFMVOcyhqDk3LQrnAl/RT5MNKhvmOXbJeWx\npTF6x36RMm8X5T+/50c2gGpske0wl3v2732mbHmbVWdsurwosLU4XXx0RA6LiRs8\ncwIDAQAB\n-----END PUBLIC KEY-----'}
2022-01-17 17:38:17,159 DEBUG    core.py     Correct username, starting passwd check.
2022-01-17 17:38:17,159 DEBUG    core.py     Auth message = {'response': 511, 'bin': '49e8b63adf98272154129d11f768aa3f8d4bd66fa66d0824a5631df86a9719dec59aa50c7bb5ff6a11eb3f9a1f3e4711ea6f96baa70050061d472c5942486d38'}
2022-01-17 17:38:52,226 DEBUG    server.py   Инициализация парсера аргументов коммандной строки: ['C:/Users/PanovaM/Desktop/Geekbrains/PyQT/Lesson5/server.py']
2022-01-17 17:38:52,226 DEBUG    server.py   Аргументы успешно загружены.
2022-01-17 17:38:52,226 DEBUG    decos.py    Была вызвана функция arg_parser с параметрами ('7777', ''), {}.Вызов из модуля __main__.Вызов из функции main() компонента server.py
2022-01-17 17:38:52,257 INFO     core.py     Запущен сервер, порт для подключений: 7777, адрес с которого принимаются подключения: . Если адрес не указан, принимаются соединения с любых адресов.
2022-01-17 17:39:17,981 DEBUG    decos.py    Была вызвана функция arg_parser с параметрами (), {}.Вызов из модуля __main__.Вызов из функции arg_parser() компонента client.py
2022-01-17 17:39:22,942 INFO     core.py     Установлено соедение с ПК ('127.0.0.1', 50310)
2022-01-17 17:39:23,450 DEBUG    core.py     Start auth process for {'account_name': 'test2', 'pubkey': '-----BEGIN PUBLIC KEY-----\nMIIBIjANBgkqhkiG9w0BAQEFAAOCAQ8AMIIBCgKCAQEAsyD82XiFWNTzk+5xwsfE\n8YiiWULjCjErkmqWNlVxeL40oqdHiG8TLbV/hLa9qbu4+52ntx/ev9fRc+ixvrr6\niq+y+eieI9yitBVTfLiFFMQtGi0DjYVVdGjplvtljCQxchC3rmF9yu44r14jPP5W\nCsn7DoYoSOmQtKt3a0YzpsNFa4d6wXhVIvmuAhsuPNi6rfnLNCL49XyzWtoCHEVN\nOVsJpO6Zmsyc/Q5irHfjZ5krJEV9dxPAaQkzdTXmCRh3OEL0OZ9zJpVPbV/bGtuc\nIbNZwSh2C+aPL+65ux2v0pXEyBSnjDLq9UiRnJ/mVl+VYbI/1KhKxRZnruE8Dbvw\nzwIDAQAB\n-----END PUBLIC KEY-----'}
2022-01-17 17:39:23,450 DEBUG    core.py     Correct username, starting passwd check.
2022-01-17 17:39:23,450 DEBUG    core.py     Auth message = {'response': 511, 'bin': '7d9c483330195f8d7a0feea9ea0d5975773e4cd7956eea03696453995103a3bec03eb31a500f82855d29c27e25783d9b57b35ee329a1f8ff56f99e6006f1711f'}
2022-01-17 17:40:00,604 DEBUG    decos.py    Была вызвана функция arg_parser с параметрами (), {}.Вызов из модуля __main__.Вызов из функции arg_parser() компонента client.py
2022-01-17 17:40:00,604 DEBUG    decos.py    Была вызвана функция arg_parser с параметрами (), {}.Вызов из модуля __main__.Вызов из функции arg_parser() компонента client.py
2022-01-17 17:40:01,002 INFO     core.py     Установлено соедение с ПК ('127.0.0.1', 50389)
2022-01-17 17:40:01,002 INFO     core.py     Установлено соедение с ПК ('127.0.0.1', 50390)
2022-01-17 17:40:01,517 DEBUG    core.py     Start auth process for {'account_name': 'test1', 'pubkey': '-----BEGIN PUBLIC KEY-----\nMIIBIjANBgkqhkiG9w0BAQEFAAOCAQ8AMIIBCgKCAQEAiIvkZ/4aFCOitj4mqHCU\nb0Vw3v+HLBHFFx3dNAsGh49AbIBkt7DqCEIPtOFLbJrLuyrN/zYfp2KJW0B0dmJ8\nViJ3y1LI0u+ZuVJL+GSLtMzO5v1M9h+D2tetKU20wuh/xqqcsGq5kaJ+tTDQ1Xsi\ngP1aj+gqhSu4/rG72PEmosvTp/AX35i/E1WufsUi/MI2xJ4lwVEyVWaTSUo9GClJ\nQl38CkAJubuyRxVNvcLYm1ZfWuTs4ZFMVOcyhqDk3LQrnAl/RT5MNKhvmOXbJeWx\npTF6x36RMm8X5T+/50c2gGpske0wl3v2732mbHmbVWdsurwosLU4XXx0RA6LiRs8\ncwIDAQAB\n-----END PUBLIC KEY-----'}
2022-01-17 17:40:01,517 DEBUG    core.py     Correct username, starting passwd check.
2022-01-17 17:40:01,517 DEBUG    core.py     Auth message = {'response': 511, 'bin': '4ffeb91b5e1f653e7f641971d1bd2e7b76239bf02cf8ba882f4d70d020ba3d56151fd5d975a34eea96d613af06c8fd0e35bd00b8149ed8c67cf7991baa03ffd7'}
2022-01-17 17:40:08,596 DEBUG    decos.py    Была вызвана функция arg_parser с параметрами (), {}.Вызов из модуля __main__.Вызов из функции arg_parser() компонента client.py
2022-01-17 17:41:49,866 DEBUG    server.py   Инициализация парсера аргументов коммандной строки: ['server.py']
2022-01-17 17:41:49,869 DEBUG    server.py   Аргументы успешно загружены.
2022-01-17 17:41:49,870 DEBUG    decos.py    Была вызвана функция arg_parser с параметрами ('7777', ''), {}.Вызов из модуля __main__.Вызов из функции main() компонента server.py
2022-01-17 17:41:49,887 INFO     core.py     Запущен сервер, порт для подключений: 7777, адрес с которого принимаются подключения: . Если адрес не указан, принимаются соединения с любых адресов.
2022-01-17 17:42:00,648 DEBUG    decos.py    Была вызвана функция arg_parser с параметрами (), {}.Вызов из модуля __main__.Вызов из функции arg_parser() компонента client.py
2022-01-17 17:42:00,648 DEBUG    decos.py    Была вызвана функция arg_parser с параметрами (), {}.Вызов из модуля __main__.Вызов из функции arg_parser() компонента client.py
2022-01-17 17:42:01,038 INFO     core.py     Установлено соедение с ПК ('127.0.0.1', 50610)
2022-01-17 17:42:01,038 INFO     core.py     Установлено соедение с ПК ('127.0.0.1', 50611)
2022-01-17 17:42:01,540 DEBUG    core.py     Start auth process for {'account_name': 'test1', 'pubkey': '-----BEGIN PUBLIC KEY-----\nMIIBIjANBgkqhkiG9w0BAQEFAAOCAQ8AMIIBCgKCAQEAiIvkZ/4aFCOitj4mqHCU\nb0Vw3v+HLBHFFx3dNAsGh49AbIBkt7DqCEIPtOFLbJrLuyrN/zYfp2KJW0B0dmJ8\nViJ3y1LI0u+ZuVJL+GSLtMzO5v1M9h+D2tetKU20wuh/xqqcsGq5kaJ+tTDQ1Xsi\ngP1aj+gqhSu4/rG72PEmosvTp/AX35i/E1WufsUi/MI2xJ4lwVEyVWaTSUo9GClJ\nQl38CkAJubuyRxVNvcLYm1ZfWuTs4ZFMVOcyhqDk3LQrnAl/RT5MNKhvmOXbJeWx\npTF6x36RMm8X5T+/50c2gGpske0wl3v2732mbHmbVWdsurwosLU4XXx0RA6LiRs8\ncwIDAQAB\n-----END PUBLIC KEY-----'}
2022-01-17 17:42:01,540 DEBUG    core.py     Correct username, starting passwd check.
2022-01-17 17:42:01,540 DEBUG    core.py     Auth message = {'response': 511, 'bin': '0f033081b5342a82e311c02968aac9901a67e0604dda019b5acce2ee30ef0a10eb6972e133bbe99b106ddcf434a2ed0b6036e3d868231221a65abfa54894d263'}
2022-01-17 17:45:28,399 DEBUG    server.py   Инициализация парсера аргументов коммандной строки: ['server.py']
2022-01-17 17:45:28,399 DEBUG    server.py   Аргументы успешно загружены.
2022-01-17 17:45:28,399 DEBUG    decos.py    Была вызвана функция arg_parser с параметрами ('7777', ''), {}.Вызов из модуля __main__.Вызов из функции main() компонента server.py
2022-01-17 17:45:28,466 INFO     core.py     Запущен сервер, порт для подключений: 7777, адрес с которого принимаются подключения: . Если адрес не указан, принимаются соединения с любых адресов.
2022-01-17 17:45:54,580 DEBUG    decos.py    Была вызвана функция arg_parser с параметрами (), {}.Вызов из модуля __main__.Вызов из функции arg_parser() компонента client.py
2022-01-17 17:45:54,580 DEBUG    decos.py    Была вызвана функция arg_parser с параметрами (), {}.Вызов из модуля __main__.Вызов из функции arg_parser() компонента client.py
2022-01-17 17:45:55,009 INFO     core.py     Установлено соедение с ПК ('127.0.0.1', 50895)
2022-01-17 17:45:55,009 INFO     core.py     Установлено соедение с ПК ('127.0.0.1', 50896)
2022-01-17 17:45:55,510 DEBUG    core.py     Start auth process for {'account_name': 'test2', 'pubkey': '-----BEGIN PUBLIC KEY-----\nMIIBIjANBgkqhkiG9w0BAQEFAAOCAQ8AMIIBCgKCAQEAsyD82XiFWNTzk+5xwsfE\n8YiiWULjCjErkmqWNlVxeL40oqdHiG8TLbV/hLa9qbu4+52ntx/ev9fRc+ixvrr6\niq+y+eieI9yitBVTfLiFFMQtGi0DjYVVdGjplvtljCQxchC3rmF9yu44r14jPP5W\nCsn7DoYoSOmQtKt3a0YzpsNFa4d6wXhVIvmuAhsuPNi6rfnLNCL49XyzWtoCHEVN\nOVsJpO6Zmsyc/Q5irHfjZ5krJEV9dxPAaQkzdTXmCRh3OEL0OZ9zJpVPbV/bGtuc\nIbNZwSh2C+aPL+65ux2v0pXEyBSnjDLq9UiRnJ/mVl+VYbI/1KhKxRZnruE8Dbvw\nzwIDAQAB\n-----END PUBLIC KEY-----'}
2022-01-17 17:45:55,511 DEBUG    core.py     Correct username, starting passwd check.
2022-01-17 17:45:55,516 DEBUG    core.py     Auth message = {'response': 511, 'bin': '1452337fbbb54e52580a6c0ccc1bb84bd9adac5a08985786b7a77c039194aaea74b56b0d284e3fa4aa9ff5e06edcdd9019028f2cfdeaf92f918e0bf39b587c6c'}
2022-01-17 17:45:55,545 DEBUG    core.py     Start auth process for {'account_name': 'test1', 'pubkey': '-----BEGIN PUBLIC KEY-----\nMIIBIjANBgkqhkiG9w0BAQEFAAOCAQ8AMIIBCgKCAQEAiIvkZ/4aFCOitj4mqHCU\nb0Vw3v+HLBHFFx3dNAsGh49AbIBkt7DqCEIPtOFLbJrLuyrN/zYfp2KJW0B0dmJ8\nViJ3y1LI0u+ZuVJL+GSLtMzO5v1M9h+D2tetKU20wuh/xqqcsGq5kaJ+tTDQ1Xsi\ngP1aj+gqhSu4/rG72PEmosvTp/AX35i/E1WufsUi/MI2xJ4lwVEyVWaTSUo9GClJ\nQl38CkAJubuyRxVNvcLYm1ZfWuTs4ZFMVOcyhqDk3LQrnAl/RT5MNKhvmOXbJeWx\npTF6x36RMm8X5T+/50c2gGpske0wl3v2732mbHmbVWdsurwosLU4XXx0RA6LiRs8\ncwIDAQAB\n-----END PUBLIC KEY-----'}
2022-01-17 17:45:55,555 DEBUG    core.py     Correct username, starting passwd check.
2022-01-17 17:45:55,555 DEBUG    core.py     Auth message = {'response': 511, 'bin': 'feabc1ad488d10d340e6202ea7aa2cbfc55577356a540999bb096fed9148170cb43eb63591e427ede5b6d7ff25035ff460744a39265f319563f92ec4b997fda2'}
2022-01-17 17:46:15,405 DEBUG    core.py     Getting data from client exception.
Traceback (most recent call last):
  File "C:\Users\PanovaM\Desktop\Geekbrains\PyQT\Lesson5\server_file\core.py", line 75, in run
    self.process_client_massage(
  File "C:\Users\PanovaM\Desktop\Geekbrains\PyQT\Lesson5\server_file\core.py", line 120, in process_client_massage
    self.process_message(message)
TypeError: process_message() missing 1 required positional argument: 'listen_socks'
2022-01-17 17:46:15,407 INFO     core.py     Клиент ('127.0.0.1', 50896) отключился от сервера.
2022-01-17 17:49:18,995 DEBUG    server.py   Инициализация парсера аргументов коммандной строки: ['server.py']
2022-01-17 17:49:18,995 DEBUG    server.py   Аргументы успешно загружены.
2022-01-17 17:49:18,995 DEBUG    decos.py    Была вызвана функция arg_parser с параметрами ('7777', ''), {}.Вызов из модуля __main__.Вызов из функции main() компонента server.py
2022-01-17 17:49:19,058 INFO     core.py     Запущен сервер, порт для подключений: 7777, адрес с которого принимаются подключения: . Если адрес не указан, принимаются соединения с любых адресов.
2022-01-17 17:49:49,495 DEBUG    decos.py    Была вызвана функция arg_parser с параметрами (), {}.Вызов из модуля __main__.Вызов из функции arg_parser() компонента client.py
2022-01-17 17:49:49,495 DEBUG    decos.py    Была вызвана функция arg_parser с параметрами (), {}.Вызов из модуля __main__.Вызов из функции arg_parser() компонента client.py
2022-01-17 17:49:49,884 INFO     core.py     Установлено соедение с ПК ('127.0.0.1', 51055)
2022-01-17 17:49:49,884 INFO     core.py     Установлено соедение с ПК ('127.0.0.1', 51056)
2022-01-17 17:49:50,401 DEBUG    core.py     Start auth process for {'account_name': 'test1', 'pubkey': '-----BEGIN PUBLIC KEY-----\nMIIBIjANBgkqhkiG9w0BAQEFAAOCAQ8AMIIBCgKCAQEAiIvkZ/4aFCOitj4mqHCU\nb0Vw3v+HLBHFFx3dNAsGh49AbIBkt7DqCEIPtOFLbJrLuyrN/zYfp2KJW0B0dmJ8\nViJ3y1LI0u+ZuVJL+GSLtMzO5v1M9h+D2tetKU20wuh/xqqcsGq5kaJ+tTDQ1Xsi\ngP1aj+gqhSu4/rG72PEmosvTp/AX35i/E1WufsUi/MI2xJ4lwVEyVWaTSUo9GClJ\nQl38CkAJubuyRxVNvcLYm1ZfWuTs4ZFMVOcyhqDk3LQrnAl/RT5MNKhvmOXbJeWx\npTF6x36RMm8X5T+/50c2gGpske0wl3v2732mbHmbVWdsurwosLU4XXx0RA6LiRs8\ncwIDAQAB\n-----END PUBLIC KEY-----'}
2022-01-17 17:49:50,402 DEBUG    core.py     Correct username, starting passwd check.
2022-01-17 17:49:50,408 DEBUG    core.py     Auth message = {'response': 511, 'bin': '7e35cf542a503642a3d54b9c917730e6bdbe68106129d64a75b62ddb5ab4e69fb7b365bd568339119597568614498a1a76d0a6b8ad693fda65e78a332c177b5e'}
2022-01-17 17:49:50,434 DEBUG    core.py     Start auth process for {'account_name': 'test2', 'pubkey': '-----BEGIN PUBLIC KEY-----\nMIIBIjANBgkqhkiG9w0BAQEFAAOCAQ8AMIIBCgKCAQEAsyD82XiFWNTzk+5xwsfE\n8YiiWULjCjErkmqWNlVxeL40oqdHiG8TLbV/hLa9qbu4+52ntx/ev9fRc+ixvrr6\niq+y+eieI9yitBVTfLiFFMQtGi0DjYVVdGjplvtljCQxchC3rmF9yu44r14jPP5W\nCsn7DoYoSOmQtKt3a0YzpsNFa4d6wXhVIvmuAhsuPNi6rfnLNCL49XyzWtoCHEVN\nOVsJpO6Zmsyc/Q5irHfjZ5krJEV9dxPAaQkzdTXmCRh3OEL0OZ9zJpVPbV/bGtuc\nIbNZwSh2C+aPL+65ux2v0pXEyBSnjDLq9UiRnJ/mVl+VYbI/1KhKxRZnruE8Dbvw\nzwIDAQAB\n-----END PUBLIC KEY-----'}
2022-01-17 17:49:50,444 DEBUG    core.py     Correct username, starting passwd check.
2022-01-17 17:49:50,446 DEBUG    core.py     Auth message = {'response': 511, 'bin': 'c30a5749e27e77a98b0c91393ffa228f5effdcba9688352daf98bc64f3e579d1893515993cecfa0efe6d826614c0f32724c16ffe2a61de49429a0e2af9b3b3d2'}
2022-01-17 17:50:07,821 DEBUG    core.py     Getting data from client exception.
Traceback (most recent call last):
  File "C:\Users\PanovaM\Desktop\Geekbrains\PyQT\Lesson5\server_file\core.py", line 75, in run
    self.process_client_massage(
  File "C:\Users\PanovaM\Desktop\Geekbrains\PyQT\Lesson5\server_file\core.py", line 120, in process_client_massage
    self.process_message(message)
TypeError: process_message() missing 1 required positional argument: 'listen_socks'
2022-01-17 17:50:07,822 INFO     core.py     Клиент ('127.0.0.1', 51055) отключился от сервера.
2022-01-17 18:30:33,585 DEBUG    server.py   Инициализация парсера аргументов коммандной строки: ['C:/Users/PanovaM/Desktop/Geekbrains/PyQT/Lesson5/server.py']
2022-01-17 18:30:33,585 DEBUG    server.py   Аргументы успешно загружены.
2022-01-17 18:30:33,585 DEBUG    decos.py    Была вызвана функция arg_parser с параметрами ('7777', ''), {}.Вызов из модуля __main__.Вызов из функции main() компонента server.py
2022-01-17 18:30:33,601 INFO     core.py     Запущен сервер, порт для подключений: 7777, адрес с которого принимаются подключения: . Если адрес не указан, принимаются соединения с любых адресов.
2022-01-17 18:31:06,249 DEBUG    server.py   Инициализация парсера аргументов коммандной строки: ['server.py']
2022-01-17 18:31:06,265 DEBUG    server.py   Аргументы успешно загружены.
2022-01-17 18:31:06,265 DEBUG    decos.py    Была вызвана функция arg_parser с параметрами ('7777', ''), {}.Вызов из модуля __main__.Вызов из функции main() компонента server.py
2022-01-17 18:31:06,281 INFO     core.py     Запущен сервер, порт для подключений: 7777, адрес с которого принимаются подключения: . Если адрес не указан, принимаются соединения с любых адресов.
2022-01-17 18:31:14,094 DEBUG    decos.py    Была вызвана функция arg_parser с параметрами (), {}.Вызов из модуля __main__.Вызов из функции arg_parser() компонента client.py
2022-01-17 18:31:14,094 DEBUG    decos.py    Была вызвана функция arg_parser с параметрами (), {}.Вызов из модуля __main__.Вызов из функции arg_parser() компонента client.py
2022-01-17 18:31:14,499 INFO     core.py     Установлено соедение с ПК ('127.0.0.1', 56727)
2022-01-17 18:31:14,500 INFO     core.py     Установлено соедение с ПК ('127.0.0.1', 56728)
2022-01-17 18:31:15,014 DEBUG    core.py     Start auth process for {'account_name': 'test1', 'pubkey': '-----BEGIN PUBLIC KEY-----\nMIIBIjANBgkqhkiG9w0BAQEFAAOCAQ8AMIIBCgKCAQEAiIvkZ/4aFCOitj4mqHCU\nb0Vw3v+HLBHFFx3dNAsGh49AbIBkt7DqCEIPtOFLbJrLuyrN/zYfp2KJW0B0dmJ8\nViJ3y1LI0u+ZuVJL+GSLtMzO5v1M9h+D2tetKU20wuh/xqqcsGq5kaJ+tTDQ1Xsi\ngP1aj+gqhSu4/rG72PEmosvTp/AX35i/E1WufsUi/MI2xJ4lwVEyVWaTSUo9GClJ\nQl38CkAJubuyRxVNvcLYm1ZfWuTs4ZFMVOcyhqDk3LQrnAl/RT5MNKhvmOXbJeWx\npTF6x36RMm8X5T+/50c2gGpske0wl3v2732mbHmbVWdsurwosLU4XXx0RA6LiRs8\ncwIDAQAB\n-----END PUBLIC KEY-----'}
2022-01-17 18:31:15,020 DEBUG    core.py     Correct username, starting passwd check.
2022-01-17 18:31:15,022 DEBUG    core.py     Auth message = {'response': 511, 'bin': '46c2809f2e6729fb3bbc3c99acd375b97dd860566b97e9823bcee2b1029cb614c9af9ad79fcf98985215fef9b1fa11530ef98b5395d02fe40908ff3434185c3c'}
2022-01-17 18:31:15,055 DEBUG    core.py     Start auth process for {'account_name': 'test2', 'pubkey': '-----BEGIN PUBLIC KEY-----\nMIIBIjANBgkqhkiG9w0BAQEFAAOCAQ8AMIIBCgKCAQEAsyD82XiFWNTzk+5xwsfE\n8YiiWULjCjErkmqWNlVxeL40oqdHiG8TLbV/hLa9qbu4+52ntx/ev9fRc+ixvrr6\niq+y+eieI9yitBVTfLiFFMQtGi0DjYVVdGjplvtljCQxchC3rmF9yu44r14jPP5W\nCsn7DoYoSOmQtKt3a0YzpsNFa4d6wXhVIvmuAhsuPNi6rfnLNCL49XyzWtoCHEVN\nOVsJpO6Zmsyc/Q5irHfjZ5krJEV9dxPAaQkzdTXmCRh3OEL0OZ9zJpVPbV/bGtuc\nIbNZwSh2C+aPL+65ux2v0pXEyBSnjDLq9UiRnJ/mVl+VYbI/1KhKxRZnruE8Dbvw\nzwIDAQAB\n-----END PUBLIC KEY-----'}
2022-01-17 18:31:15,067 DEBUG    core.py     Correct username, starting passwd check.
2022-01-17 18:31:15,069 DEBUG    core.py     Auth message = {'response': 511, 'bin': '443119e81efc91e6181b4711308001515f52766465258b55cd8d729d9d63c336c6ba8a4d9f8c26c22bd601d2b158c92000c988f5dfa906ae01d2e173a37d7fdd'}
2022-01-17 18:31:34,351 DEBUG    server.py   Инициализация парсера аргументов коммандной строки: ['server.py']
2022-01-17 18:31:34,351 DEBUG    server.py   Аргументы успешно загружены.
2022-01-17 18:31:34,351 DEBUG    decos.py    Была вызвана функция arg_parser с параметрами ('7777', ''), {}.Вызов из модуля __main__.Вызов из функции main() компонента server.py
2022-01-17 18:31:34,405 INFO     core.py     Запущен сервер, порт для подключений: 7777, адрес с которого принимаются подключения: . Если адрес не указан, принимаются соединения с любых адресов.
2022-01-17 18:32:05,449 DEBUG    decos.py    Была вызвана функция arg_parser с параметрами (), {}.Вызов из модуля __main__.Вызов из функции arg_parser() компонента client.py
2022-01-17 18:32:05,856 INFO     core.py     Установлено соедение с ПК ('127.0.0.1', 56783)
2022-01-17 18:32:05,868 INFO     core.py     Установлено соедение с ПК ('127.0.0.1', 56784)
2022-01-17 18:32:05,868 DEBUG    core.py     Start auth process for {'account_name': 'test1', 'pubkey': '-----BEGIN PUBLIC KEY-----\nMIIBIjANBgkqhkiG9w0BAQEFAAOCAQ8AMIIBCgKCAQEAiIvkZ/4aFCOitj4mqHCU\nb0Vw3v+HLBHFFx3dNAsGh49AbIBkt7DqCEIPtOFLbJrLuyrN/zYfp2KJW0B0dmJ8\nViJ3y1LI0u+ZuVJL+GSLtMzO5v1M9h+D2tetKU20wuh/xqqcsGq5kaJ+tTDQ1Xsi\ngP1aj+gqhSu4/rG72PEmosvTp/AX35i/E1WufsUi/MI2xJ4lwVEyVWaTSUo9GClJ\nQl38CkAJubuyRxVNvcLYm1ZfWuTs4ZFMVOcyhqDk3LQrnAl/RT5MNKhvmOXbJeWx\npTF6x36RMm8X5T+/50c2gGpske0wl3v2732mbHmbVWdsurwosLU4XXx0RA6LiRs8\ncwIDAQAB\n-----END PUBLIC KEY-----'}
2022-01-17 18:32:05,868 DEBUG    core.py     Correct username, starting passwd check.
2022-01-17 18:32:05,868 DEBUG    core.py     Auth message = {'response': 511, 'bin': '9723c53663075eb81505f342ba5e43e1ca8d12fc041d81ae58e992355306da928a69587852dbf16e0cca81e6d04298aa37a5aa615d143387a31ce8c62abbb5ca'}
2022-01-17 18:32:06,402 DEBUG    core.py     Start auth process for {'account_name': 'test2', 'pubkey': '-----BEGIN PUBLIC KEY-----\nMIIBIjANBgkqhkiG9w0BAQEFAAOCAQ8AMIIBCgKCAQEAsyD82XiFWNTzk+5xwsfE\n8YiiWULjCjErkmqWNlVxeL40oqdHiG8TLbV/hLa9qbu4+52ntx/ev9fRc+ixvrr6\niq+y+eieI9yitBVTfLiFFMQtGi0DjYVVdGjplvtljCQxchC3rmF9yu44r14jPP5W\nCsn7DoYoSOmQtKt3a0YzpsNFa4d6wXhVIvmuAhsuPNi6rfnLNCL49XyzWtoCHEVN\nOVsJpO6Zmsyc/Q5irHfjZ5krJEV9dxPAaQkzdTXmCRh3OEL0OZ9zJpVPbV/bGtuc\nIbNZwSh2C+aPL+65ux2v0pXEyBSnjDLq9UiRnJ/mVl+VYbI/1KhKxRZnruE8Dbvw\nzwIDAQAB\n-----END PUBLIC KEY-----'}
2022-01-17 18:32:06,403 DEBUG    core.py     Correct username, starting passwd check.
2022-01-17 18:32:06,403 DEBUG    core.py     Auth message = {'response': 511, 'bin': 'cce6fe3836c8700bbdb73865c04ce0dc7d66f912e2a6fe6d710fd539e28919ad2487e5987a87398d1904f1c11bf8d0e601b43d1b2bc3c3fa88618623ae1474a4'}
2022-01-17 18:32:23,229 DEBUG    core.py     Getting data from client exception.
Traceback (most recent call last):
  File "C:\Users\PanovaM\Desktop\Geekbrains\PyQT\Lesson5\server_file\core.py", line 75, in run
    self.process_client_massage(
  File "C:\Users\PanovaM\Desktop\Geekbrains\PyQT\Lesson5\server_file\core.py", line 120, in process_client_massage
    self.process_message(message)
TypeError: process_message() missing 1 required positional argument: 'listen_socks'
2022-01-17 18:32:23,231 INFO     core.py     Клиент ('127.0.0.1', 56783) отключился от сервера.
2022-01-17 18:34:54,854 DEBUG    decos.py    Была вызвана функция arg_parser с параметрами (), {}.Вызов из модуля __main__.Вызов из функции arg_parser() компонента client.py
2022-01-17 18:35:01,570 INFO     core.py     Установлено соедение с ПК ('127.0.0.1', 56954)
2022-01-17 18:35:02,084 DEBUG    core.py     Start auth process for {'account_name': 'test1', 'pubkey': '-----BEGIN PUBLIC KEY-----\nMIIBIjANBgkqhkiG9w0BAQEFAAOCAQ8AMIIBCgKCAQEAiIvkZ/4aFCOitj4mqHCU\nb0Vw3v+HLBHFFx3dNAsGh49AbIBkt7DqCEIPtOFLbJrLuyrN/zYfp2KJW0B0dmJ8\nViJ3y1LI0u+ZuVJL+GSLtMzO5v1M9h+D2tetKU20wuh/xqqcsGq5kaJ+tTDQ1Xsi\ngP1aj+gqhSu4/rG72PEmosvTp/AX35i/E1WufsUi/MI2xJ4lwVEyVWaTSUo9GClJ\nQl38CkAJubuyRxVNvcLYm1ZfWuTs4ZFMVOcyhqDk3LQrnAl/RT5MNKhvmOXbJeWx\npTF6x36RMm8X5T+/50c2gGpske0wl3v2732mbHmbVWdsurwosLU4XXx0RA6LiRs8\ncwIDAQAB\n-----END PUBLIC KEY-----'}
2022-01-17 18:35:02,087 DEBUG    core.py     Correct username, starting passwd check.
2022-01-17 18:35:02,089 DEBUG    core.py     Auth message = {'response': 511, 'bin': '38ebcc307c0733b4e2bf15f627a1fda860f1f1eaa860552cbfd20b0fc1eeeea9a7016c741f2936d4ecbfa73211e2c8959dddee05361231dea54403e4f5b7bd5c'}
2022-01-17 18:35:13,273 DEBUG    core.py     Getting data from client exception.
Traceback (most recent call last):
  File "C:\Users\PanovaM\Desktop\Geekbrains\PyQT\Lesson5\server_file\core.py", line 75, in run
    self.process_client_massage(
  File "C:\Users\PanovaM\Desktop\Geekbrains\PyQT\Lesson5\server_file\core.py", line 120, in process_client_massage
    self.process_message(message)
TypeError: process_message() missing 1 required positional argument: 'listen_socks'
2022-01-17 18:35:13,274 INFO     core.py     Клиент ('127.0.0.1', 56954) отключился от сервера.
2022-01-17 18:40:21,159 DEBUG    decos.py    Была вызвана функция arg_parser с параметрами (), {}.Вызов из модуля __main__.Вызов из функции arg_parser() компонента client.py
2022-01-17 18:40:28,271 INFO     core.py     Установлено соедение с ПК ('127.0.0.1', 57382)
2022-01-17 18:40:28,792 DEBUG    core.py     Start auth process for {'account_name': 'test1', 'pubkey': '-----BEGIN PUBLIC KEY-----\nMIIBIjANBgkqhkiG9w0BAQEFAAOCAQ8AMIIBCgKCAQEAiIvkZ/4aFCOitj4mqHCU\nb0Vw3v+HLBHFFx3dNAsGh49AbIBkt7DqCEIPtOFLbJrLuyrN/zYfp2KJW0B0dmJ8\nViJ3y1LI0u+ZuVJL+GSLtMzO5v1M9h+D2tetKU20wuh/xqqcsGq5kaJ+tTDQ1Xsi\ngP1aj+gqhSu4/rG72PEmosvTp/AX35i/E1WufsUi/MI2xJ4lwVEyVWaTSUo9GClJ\nQl38CkAJubuyRxVNvcLYm1ZfWuTs4ZFMVOcyhqDk3LQrnAl/RT5MNKhvmOXbJeWx\npTF6x36RMm8X5T+/50c2gGpske0wl3v2732mbHmbVWdsurwosLU4XXx0RA6LiRs8\ncwIDAQAB\n-----END PUBLIC KEY-----'}
2022-01-17 18:40:28,794 DEBUG    core.py     Correct username, starting passwd check.
2022-01-17 18:40:28,796 DEBUG    core.py     Auth message = {'response': 511, 'bin': '7e31de383fcd1917ad025c6c2f8c6d82b9a230be326aa2c481907d40c4b92105e3df200f20135afc449362f0869705ed69f132dba6a484cd0670d4b2ada1d149'}
2022-01-17 18:40:37,936 DEBUG    core.py     Getting data from client exception.
Traceback (most recent call last):
  File "C:\Users\PanovaM\Desktop\Geekbrains\PyQT\Lesson5\server_file\core.py", line 75, in run
    self.process_client_massage(
  File "C:\Users\PanovaM\Desktop\Geekbrains\PyQT\Lesson5\server_file\core.py", line 120, in process_client_massage
    self.process_message(message)
TypeError: process_message() missing 1 required positional argument: 'listen_socks'
2022-01-17 18:40:37,936 INFO     core.py     Клиент ('127.0.0.1', 57382) отключился от сервера.
2022-01-17 18:44:28,630 DEBUG    decos.py    Была вызвана функция arg_parser с параметрами (), {}.Вызов из модуля __main__.Вызов из функции arg_parser() компонента client.py
2022-01-17 18:44:46,714 DEBUG    server.py   Инициализация парсера аргументов коммандной строки: ['server.py']
2022-01-17 18:44:46,714 DEBUG    server.py   Аргументы успешно загружены.
2022-01-17 18:44:46,714 DEBUG    decos.py    Была вызвана функция arg_parser с параметрами ('7777', ''), {}.Вызов из модуля __main__.Вызов из функции main() компонента server.py
2022-01-17 18:44:46,730 INFO     core.py     Запущен сервер, порт для подключений: 7777, адрес с которого принимаются подключения: . Если адрес не указан, принимаются соединения с любых адресов.
2022-01-17 18:44:54,017 DEBUG    decos.py    Была вызвана функция arg_parser с параметрами (), {}.Вызов из модуля __main__.Вызов из функции arg_parser() компонента client.py
2022-01-17 18:44:54,017 DEBUG    decos.py    Была вызвана функция arg_parser с параметрами (), {}.Вызов из модуля __main__.Вызов из функции arg_parser() компонента client.py
2022-01-17 18:44:54,412 INFO     core.py     Установлено соедение с ПК ('127.0.0.1', 57976)
2022-01-17 18:44:54,412 INFO     core.py     Установлено соедение с ПК ('127.0.0.1', 57977)
2022-01-17 18:44:54,919 DEBUG    core.py     Start auth process for {'account_name': 'test2', 'pubkey': '-----BEGIN PUBLIC KEY-----\nMIIBIjANBgkqhkiG9w0BAQEFAAOCAQ8AMIIBCgKCAQEAsyD82XiFWNTzk+5xwsfE\n8YiiWULjCjErkmqWNlVxeL40oqdHiG8TLbV/hLa9qbu4+52ntx/ev9fRc+ixvrr6\niq+y+eieI9yitBVTfLiFFMQtGi0DjYVVdGjplvtljCQxchC3rmF9yu44r14jPP5W\nCsn7DoYoSOmQtKt3a0YzpsNFa4d6wXhVIvmuAhsuPNi6rfnLNCL49XyzWtoCHEVN\nOVsJpO6Zmsyc/Q5irHfjZ5krJEV9dxPAaQkzdTXmCRh3OEL0OZ9zJpVPbV/bGtuc\nIbNZwSh2C+aPL+65ux2v0pXEyBSnjDLq9UiRnJ/mVl+VYbI/1KhKxRZnruE8Dbvw\nzwIDAQAB\n-----END PUBLIC KEY-----'}
2022-01-17 18:44:54,919 DEBUG    core.py     Correct username, starting passwd check.
2022-01-17 18:44:54,919 DEBUG    core.py     Auth message = {'response': 511, 'bin': 'd80b2a0ce9456d13823f226bfd17c5f0a63a7fc641f5f8e1942fdb6bedf9649d93421b2fa46779b4004f9692bc61f34e56534f70880ac4468511b284ac9e922f'}
2022-01-17 18:45:49,212 DEBUG    server.py   Инициализация парсера аргументов коммандной строки: ['server.py']
2022-01-17 18:45:49,212 DEBUG    server.py   Аргументы успешно загружены.
2022-01-17 18:45:49,212 DEBUG    decos.py    Была вызвана функция arg_parser с параметрами ('7777', ''), {}.Вызов из модуля __main__.Вызов из функции main() компонента server.py
2022-01-17 18:45:49,268 INFO     core.py     Запущен сервер, порт для подключений: 7777, адрес с которого принимаются подключения: . Если адрес не указан, принимаются соединения с любых адресов.
2022-01-17 18:46:18,620 DEBUG    decos.py    Была вызвана функция arg_parser с параметрами (), {}.Вызов из модуля __main__.Вызов из функции arg_parser() компонента client.py
2022-01-17 18:46:18,620 DEBUG    decos.py    Была вызвана функция arg_parser с параметрами (), {}.Вызов из модуля __main__.Вызов из функции arg_parser() компонента client.py
2022-01-17 18:46:19,038 INFO     core.py     Установлено соедение с ПК ('127.0.0.1', 58163)
2022-01-17 18:46:19,038 INFO     core.py     Установлено соедение с ПК ('127.0.0.1', 58164)
2022-01-17 18:46:19,545 DEBUG    core.py     Start auth process for {'account_name': 'test2', 'pubkey': '-----BEGIN PUBLIC KEY-----\nMIIBIjANBgkqhkiG9w0BAQEFAAOCAQ8AMIIBCgKCAQEAsyD82XiFWNTzk+5xwsfE\n8YiiWULjCjErkmqWNlVxeL40oqdHiG8TLbV/hLa9qbu4+52ntx/ev9fRc+ixvrr6\niq+y+eieI9yitBVTfLiFFMQtGi0DjYVVdGjplvtljCQxchC3rmF9yu44r14jPP5W\nCsn7DoYoSOmQtKt3a0YzpsNFa4d6wXhVIvmuAhsuPNi6rfnLNCL49XyzWtoCHEVN\nOVsJpO6Zmsyc/Q5irHfjZ5krJEV9dxPAaQkzdTXmCRh3OEL0OZ9zJpVPbV/bGtuc\nIbNZwSh2C+aPL+65ux2v0pXEyBSnjDLq9UiRnJ/mVl+VYbI/1KhKxRZnruE8Dbvw\nzwIDAQAB\n-----END PUBLIC KEY-----'}
2022-01-17 18:46:19,545 DEBUG    core.py     Correct username, starting passwd check.
2022-01-17 18:46:19,545 DEBUG    core.py     Auth message = {'response': 511, 'bin': '28a1a5c84c48d5f9ca95fc4f18c5f5eb232104a32dfe2ea51bf06cda3f67e37790c5ad5aa7aafdfaad795a3d948f5f60cd146e4a8a469027f0376d0b115882c0'}
2022-01-17 18:46:19,570 DEBUG    core.py     Start auth process for {'account_name': 'test1', 'pubkey': '-----BEGIN PUBLIC KEY-----\nMIIBIjANBgkqhkiG9w0BAQEFAAOCAQ8AMIIBCgKCAQEAiIvkZ/4aFCOitj4mqHCU\nb0Vw3v+HLBHFFx3dNAsGh49AbIBkt7DqCEIPtOFLbJrLuyrN/zYfp2KJW0B0dmJ8\nViJ3y1LI0u+ZuVJL+GSLtMzO5v1M9h+D2tetKU20wuh/xqqcsGq5kaJ+tTDQ1Xsi\ngP1aj+gqhSu4/rG72PEmosvTp/AX35i/E1WufsUi/MI2xJ4lwVEyVWaTSUo9GClJ\nQl38CkAJubuyRxVNvcLYm1ZfWuTs4ZFMVOcyhqDk3LQrnAl/RT5MNKhvmOXbJeWx\npTF6x36RMm8X5T+/50c2gGpske0wl3v2732mbHmbVWdsurwosLU4XXx0RA6LiRs8\ncwIDAQAB\n-----END PUBLIC KEY-----'}
2022-01-17 18:46:19,570 DEBUG    core.py     Correct username, starting passwd check.
2022-01-17 18:46:19,570 DEBUG    core.py     Auth message = {'response': 511, 'bin': 'acda79e8c4a8d277257854718e5b895da4f14a3384a9b8316bb6859b24a38992207824154a0996c8d9d59ad766a53b0451a228f955d4090620a0e67823e8e380'}
2022-01-17 18:46:38,840 INFO     core.py     Отправляем сообщение пользователю test2 от пользователя test1.
2022-01-17 18:46:38,840 INFO     core.py     Отправлено сообщение пользователю test2 от пользователя test1.
2022-01-17 18:47:33,219 DEBUG    server.py   Инициализация парсера аргументов коммандной строки: ['server.py']
2022-01-17 18:47:33,219 DEBUG    server.py   Аргументы успешно загружены.
2022-01-17 18:47:33,219 DEBUG    decos.py    Была вызвана функция arg_parser с параметрами ('7777', ''), {}.Вызов из модуля __main__.Вызов из функции main() компонента server.py
2022-01-17 18:47:33,235 INFO     core.py     Запущен сервер, порт для подключений: 7777, адрес с которого принимаются подключения: . Если адрес не указан, принимаются соединения с любых адресов.
2022-01-17 18:47:40,080 DEBUG    decos.py    Была вызвана функция arg_parser с параметрами (), {}.Вызов из модуля __main__.Вызов из функции arg_parser() компонента client.py
2022-01-17 18:47:40,080 DEBUG    decos.py    Была вызвана функция arg_parser с параметрами (), {}.Вызов из модуля __main__.Вызов из функции arg_parser() компонента client.py
2022-01-17 18:47:40,464 INFO     core.py     Установлено соедение с ПК ('127.0.0.1', 58304)
2022-01-17 18:47:40,469 INFO     core.py     Установлено соедение с ПК ('127.0.0.1', 58305)
2022-01-17 18:47:40,987 DEBUG    core.py     Start auth process for {'account_name': 'test2', 'pubkey': '-----BEGIN PUBLIC KEY-----\nMIIBIjANBgkqhkiG9w0BAQEFAAOCAQ8AMIIBCgKCAQEAsyD82XiFWNTzk+5xwsfE\n8YiiWULjCjErkmqWNlVxeL40oqdHiG8TLbV/hLa9qbu4+52ntx/ev9fRc+ixvrr6\niq+y+eieI9yitBVTfLiFFMQtGi0DjYVVdGjplvtljCQxchC3rmF9yu44r14jPP5W\nCsn7DoYoSOmQtKt3a0YzpsNFa4d6wXhVIvmuAhsuPNi6rfnLNCL49XyzWtoCHEVN\nOVsJpO6Zmsyc/Q5irHfjZ5krJEV9dxPAaQkzdTXmCRh3OEL0OZ9zJpVPbV/bGtuc\nIbNZwSh2C+aPL+65ux2v0pXEyBSnjDLq9UiRnJ/mVl+VYbI/1KhKxRZnruE8Dbvw\nzwIDAQAB\n-----END PUBLIC KEY-----'}
2022-01-17 18:47:40,992 DEBUG    core.py     Correct username, starting passwd check.
2022-01-17 18:47:40,995 DEBUG    core.py     Auth message = {'response': 511, 'bin': 'abfbf879a7b33aa16f4e3663c270010a57b32fb70cc0334c1fb1a525bc6ff22362b7d404a2c1e1909d60fed5ecea672200552b2665f077e5888749f5d8ff69de'}
2022-01-17 18:48:00,654 DEBUG    server.py   Инициализация парсера аргументов коммандной строки: ['server.py']
2022-01-17 18:48:00,656 DEBUG    server.py   Аргументы успешно загружены.
2022-01-17 18:48:00,663 DEBUG    decos.py    Была вызвана функция arg_parser с параметрами ('7777', ''), {}.Вызов из модуля __main__.Вызов из функции main() компонента server.py
2022-01-17 18:48:00,712 INFO     core.py     Запущен сервер, порт для подключений: 7777, адрес с которого принимаются подключения: . Если адрес не указан, принимаются соединения с любых адресов.
2022-01-17 18:48:29,284 DEBUG    decos.py    Была вызвана функция arg_parser с параметрами (), {}.Вызов из модуля __main__.Вызов из функции arg_parser() компонента client.py
2022-01-17 18:48:29,284 DEBUG    decos.py    Была вызвана функция arg_parser с параметрами (), {}.Вызов из модуля __main__.Вызов из функции arg_parser() компонента client.py
2022-01-17 18:48:29,776 INFO     core.py     Установлено соедение с ПК ('127.0.0.1', 58380)
2022-01-17 18:48:29,781 INFO     core.py     Установлено соедение с ПК ('127.0.0.1', 58381)
2022-01-17 18:48:30,284 DEBUG    core.py     Start auth process for {'account_name': 'test2', 'pubkey': '-----BEGIN PUBLIC KEY-----\nMIIBIjANBgkqhkiG9w0BAQEFAAOCAQ8AMIIBCgKCAQEAsyD82XiFWNTzk+5xwsfE\n8YiiWULjCjErkmqWNlVxeL40oqdHiG8TLbV/hLa9qbu4+52ntx/ev9fRc+ixvrr6\niq+y+eieI9yitBVTfLiFFMQtGi0DjYVVdGjplvtljCQxchC3rmF9yu44r14jPP5W\nCsn7DoYoSOmQtKt3a0YzpsNFa4d6wXhVIvmuAhsuPNi6rfnLNCL49XyzWtoCHEVN\nOVsJpO6Zmsyc/Q5irHfjZ5krJEV9dxPAaQkzdTXmCRh3OEL0OZ9zJpVPbV/bGtuc\nIbNZwSh2C+aPL+65ux2v0pXEyBSnjDLq9UiRnJ/mVl+VYbI/1KhKxRZnruE8Dbvw\nzwIDAQAB\n-----END PUBLIC KEY-----'}
2022-01-17 18:48:30,285 DEBUG    core.py     Correct username, starting passwd check.
2022-01-17 18:48:30,285 DEBUG    core.py     Auth message = {'response': 511, 'bin': 'fe6a2f7377a6d67a3eba342daee689973e75c0fd463404a9cc5ff8660dd40aed236481269a1947581c82fa3d26dbdc3941243f2d66ac26b09a9b4b1166d091be'}
2022-01-17 18:48:30,303 DEBUG    core.py     Start auth process for {'account_name': 'test1', 'pubkey': '-----BEGIN PUBLIC KEY-----\nMIIBIjANBgkqhkiG9w0BAQEFAAOCAQ8AMIIBCgKCAQEAiIvkZ/4aFCOitj4mqHCU\nb0Vw3v+HLBHFFx3dNAsGh49AbIBkt7DqCEIPtOFLbJrLuyrN/zYfp2KJW0B0dmJ8\nViJ3y1LI0u+ZuVJL+GSLtMzO5v1M9h+D2tetKU20wuh/xqqcsGq5kaJ+tTDQ1Xsi\ngP1aj+gqhSu4/rG72PEmosvTp/AX35i/E1WufsUi/MI2xJ4lwVEyVWaTSUo9GClJ\nQl38CkAJubuyRxVNvcLYm1ZfWuTs4ZFMVOcyhqDk3LQrnAl/RT5MNKhvmOXbJeWx\npTF6x36RMm8X5T+/50c2gGpske0wl3v2732mbHmbVWdsurwosLU4XXx0RA6LiRs8\ncwIDAQAB\n-----END PUBLIC KEY-----'}
2022-01-17 18:48:30,311 DEBUG    core.py     Correct username, starting passwd check.
2022-01-17 18:48:30,311 DEBUG    core.py     Auth message = {'response': 511, 'bin': 'cfd0a35db509cb3f3570eb94f1cbc4f1f0e128515a2981ed124283dec763ca51b29bc7b9a42c7157fbf013b416b5ed75b748ed73cc80a0c002845fc047d5a2d5'}
2022-01-17 18:48:31,867 DEBUG    core.py     Getting data from client exception.
Traceback (most recent call last):
  File "C:\Users\PanovaM\Desktop\Geekbrains\PyQT\Lesson5\server_file\core.py", line 76, in run
    get_message(client_with_message), client_with_message)
  File "C:\Users\PanovaM\Desktop\Geekbrains\PyQT\Lesson5\common\utils.py", line 16, in get_message
    encoded_response = client.recv(MAX_PACAGE_LEGTH)
ConnectionResetError: [WinError 10054] Удаленный хост принудительно разорвал существующее подключение
2022-01-17 18:48:31,877 INFO     core.py     Клиент ('127.0.0.1', 58380) отключился от сервера.
2022-01-17 18:48:31,887 DEBUG    core.py     Getting data from client exception.
Traceback (most recent call last):
  File "C:\Users\PanovaM\Desktop\Geekbrains\PyQT\Lesson5\server_file\core.py", line 76, in run
    get_message(client_with_message), client_with_message)
  File "C:\Users\PanovaM\Desktop\Geekbrains\PyQT\Lesson5\common\utils.py", line 16, in get_message
    encoded_response = client.recv(MAX_PACAGE_LEGTH)
ConnectionResetError: [WinError 10054] Удаленный хост принудительно разорвал существующее подключение
2022-01-17 18:48:31,887 INFO     core.py     Клиент ('127.0.0.1', 58381) отключился от сервера.
2022-01-17 18:49:48,852 DEBUG    decos.py    Была вызвана функция main с параметрами (), {}.Вызов из модуля __main__.Вызов из функции main() компонента server.py
2022-01-17 18:50:01,374 DEBUG    server.py   Инициализация парсера аргументов коммандной строки: ['server.py']
2022-01-17 18:50:01,374 DEBUG    server.py   Аргументы успешно загружены.
2022-01-17 18:50:01,374 DEBUG    decos.py    Была вызвана функция arg_parser с параметрами ('7777', ''), {}.Вызов из модуля __main__.Вызов из функции main() компонента server.py
2022-01-17 18:50:01,433 INFO     core.py     Запущен сервер, порт для подключений: 7777, адрес с которого принимаются подключения: . Если адрес не указан, принимаются соединения с любых адресов.
2022-01-17 18:50:26,310 DEBUG    decos.py    Была вызвана функция arg_parser с параметрами (), {}.Вызов из модуля __main__.Вызов из функции arg_parser() компонента client.py
2022-01-17 18:50:26,310 DEBUG    decos.py    Была вызвана функция arg_parser с параметрами (), {}.Вызов из модуля __main__.Вызов из функции arg_parser() компонента client.py
2022-01-17 18:50:26,724 INFO     core.py     Установлено соедение с ПК ('127.0.0.1', 58566)
2022-01-17 18:50:26,724 INFO     core.py     Установлено соедение с ПК ('127.0.0.1', 58567)
2022-01-17 18:50:27,232 DEBUG    core.py     Start auth process for {'account_name': 'test2', 'pubkey': '-----BEGIN PUBLIC KEY-----\nMIIBIjANBgkqhkiG9w0BAQEFAAOCAQ8AMIIBCgKCAQEAsyD82XiFWNTzk+5xwsfE\n8YiiWULjCjErkmqWNlVxeL40oqdHiG8TLbV/hLa9qbu4+52ntx/ev9fRc+ixvrr6\niq+y+eieI9yitBVTfLiFFMQtGi0DjYVVdGjplvtljCQxchC3rmF9yu44r14jPP5W\nCsn7DoYoSOmQtKt3a0YzpsNFa4d6wXhVIvmuAhsuPNi6rfnLNCL49XyzWtoCHEVN\nOVsJpO6Zmsyc/Q5irHfjZ5krJEV9dxPAaQkzdTXmCRh3OEL0OZ9zJpVPbV/bGtuc\nIbNZwSh2C+aPL+65ux2v0pXEyBSnjDLq9UiRnJ/mVl+VYbI/1KhKxRZnruE8Dbvw\nzwIDAQAB\n-----END PUBLIC KEY-----'}
2022-01-17 18:50:27,232 DEBUG    core.py     Correct username, starting passwd check.
2022-01-17 18:50:27,232 DEBUG    core.py     Auth message = {'response': 511, 'bin': '6208601c736b139d0cbdf0f73d029f995acc90b10849c3c6f8486edfd5df3b649c50b5ee2fb3aca9a4f0cd1ced92833c3b24adcbd761f8b71da76c4f741682a6'}
2022-01-17 18:50:27,263 DEBUG    core.py     Start auth process for {'account_name': 'test1', 'pubkey': '-----BEGIN PUBLIC KEY-----\nMIIBIjANBgkqhkiG9w0BAQEFAAOCAQ8AMIIBCgKCAQEAiIvkZ/4aFCOitj4mqHCU\nb0Vw3v+HLBHFFx3dNAsGh49AbIBkt7DqCEIPtOFLbJrLuyrN/zYfp2KJW0B0dmJ8\nViJ3y1LI0u+ZuVJL+GSLtMzO5v1M9h+D2tetKU20wuh/xqqcsGq5kaJ+tTDQ1Xsi\ngP1aj+gqhSu4/rG72PEmosvTp/AX35i/E1WufsUi/MI2xJ4lwVEyVWaTSUo9GClJ\nQl38CkAJubuyRxVNvcLYm1ZfWuTs4ZFMVOcyhqDk3LQrnAl/RT5MNKhvmOXbJeWx\npTF6x36RMm8X5T+/50c2gGpske0wl3v2732mbHmbVWdsurwosLU4XXx0RA6LiRs8\ncwIDAQAB\n-----END PUBLIC KEY-----'}
2022-01-17 18:50:27,263 DEBUG    core.py     Correct username, starting passwd check.
2022-01-17 18:50:27,263 DEBUG    core.py     Auth message = {'response': 511, 'bin': '39d7796c14578a70ab22fee29bff93f1f3f54e038da636b60e73f43e7cd55c616101f7a82d24bbecca60287b73c756498c55841b968ac2deb2d74105501d4db8'}
2022-01-17 18:50:28,813 DEBUG    core.py     Getting data from client exception.
Traceback (most recent call last):
  File "C:\Users\PanovaM\Desktop\Geekbrains\PyQT\Lesson5\server_file\core.py", line 76, in run
    get_message(client_with_message), client_with_message)
  File "C:\Users\PanovaM\Desktop\Geekbrains\PyQT\Lesson5\common\utils.py", line 16, in get_message
    encoded_response = client.recv(MAX_PACAGE_LEGTH)
ConnectionResetError: [WinError 10054] Удаленный хост принудительно разорвал существующее подключение
2022-01-17 18:50:28,815 INFO     core.py     Клиент ('127.0.0.1', 58566) отключился от сервера.
2022-01-17 18:50:28,835 DEBUG    core.py     Getting data from client exception.
Traceback (most recent call last):
  File "C:\Users\PanovaM\Desktop\Geekbrains\PyQT\Lesson5\server_file\core.py", line 76, in run
    get_message(client_with_message), client_with_message)
  File "C:\Users\PanovaM\Desktop\Geekbrains\PyQT\Lesson5\common\utils.py", line 16, in get_message
    encoded_response = client.recv(MAX_PACAGE_LEGTH)
ConnectionResetError: [WinError 10054] Удаленный хост принудительно разорвал существующее подключение
2022-01-17 18:50:28,835 INFO     core.py     Клиент ('127.0.0.1', 58567) отключился от сервера.
2022-01-17 18:50:54,841 DEBUG    decos.py    Была вызвана функция main с параметрами (), {}.Вызов из модуля __main__.Вызов из функции main() компонента server.py
2022-01-17 18:51:21,730 DEBUG    server.py   Инициализация парсера аргументов коммандной строки: ['C:/Users/PanovaM/Desktop/Geekbrains/PyQT/Lesson5/server.py']
2022-01-17 18:51:21,730 DEBUG    server.py   Аргументы успешно загружены.
2022-01-17 18:51:21,730 DEBUG    decos.py    Была вызвана функция arg_parser с параметрами ('7777', ''), {}.Вызов из модуля __main__.Вызов из функции main() компонента server.py
2022-01-17 18:51:21,745 INFO     core.py     Запущен сервер, порт для подключений: 7777, адрес с которого принимаются подключения: . Если адрес не указан, принимаются соединения с любых адресов.
2022-01-17 18:51:37,394 DEBUG    decos.py    Была вызвана функция arg_parser с параметрами (), {}.Вызов из модуля __main__.Вызов из функции arg_parser() компонента client.py
2022-01-17 18:51:45,230 INFO     core.py     Установлено соедение с ПК ('127.0.0.1', 58689)
2022-01-17 18:51:45,745 DEBUG    core.py     Start auth process for {'account_name': 'test1', 'pubkey': '-----BEGIN PUBLIC KEY-----\nMIIBIjANBgkqhkiG9w0BAQEFAAOCAQ8AMIIBCgKCAQEAiIvkZ/4aFCOitj4mqHCU\nb0Vw3v+HLBHFFx3dNAsGh49AbIBkt7DqCEIPtOFLbJrLuyrN/zYfp2KJW0B0dmJ8\nViJ3y1LI0u+ZuVJL+GSLtMzO5v1M9h+D2tetKU20wuh/xqqcsGq5kaJ+tTDQ1Xsi\ngP1aj+gqhSu4/rG72PEmosvTp/AX35i/E1WufsUi/MI2xJ4lwVEyVWaTSUo9GClJ\nQl38CkAJubuyRxVNvcLYm1ZfWuTs4ZFMVOcyhqDk3LQrnAl/RT5MNKhvmOXbJeWx\npTF6x36RMm8X5T+/50c2gGpske0wl3v2732mbHmbVWdsurwosLU4XXx0RA6LiRs8\ncwIDAQAB\n-----END PUBLIC KEY-----'}
2022-01-17 18:51:45,747 DEBUG    core.py     Correct username, starting passwd check.
2022-01-17 18:51:45,749 DEBUG    core.py     Auth message = {'response': 511, 'bin': '4436257771f6ded5fe30c4e24a4c403cc01983c541678a4919fe3c646e1f85eb72346ec13230e89dc32269c64a8e4bd9a8239f617733ecf978f3845d94bad06a'}
2022-01-17 18:51:47,319 DEBUG    core.py     Getting data from client exception.
Traceback (most recent call last):
  File "C:\Users\PanovaM\Desktop\Geekbrains\PyQT\Lesson5\server_file\core.py", line 76, in run
    get_message(client_with_message), client_with_message)
  File "C:\Users\PanovaM\Desktop\Geekbrains\PyQT\Lesson5\common\utils.py", line 16, in get_message
    encoded_response = client.recv(MAX_PACAGE_LEGTH)
ConnectionResetError: [WinError 10054] Удаленный хост принудительно разорвал существующее подключение
2022-01-17 18:51:47,321 INFO     core.py     Клиент ('127.0.0.1', 58689) отключился от сервера.
